Workbook
Name SegmentaciónDeDatos_ESPECIALIDAD: #N/A
Name SegmentaciónDeDatos_ESTADO_2: #N/A
Name SegmentaciónDeDatos_ESTADO_FINAL: #N/A
Name SegmentaciónDeDatos_MOTIVO: #N/A
Name SegmentaciónDeDatos_PERIODO: #N/A
Name SegmentaciónDeDatos_PROCESO: #N/A
Name SegmentaciónDeDatos_TIPO_CONTRATO: #N/A

Sheet base pendientes viva 1a
A1: FECHA DE INGRESO DEL REQUERIMIENTO | B1: CANAL | C1: DNI | D1: NOMBRES Y APELLIDOS | E1: RUC CONTRATANTE | F1: DESCRIPCIÓN DE CONTRATANTE | G1: TENOR DEL CORREO | H1: TIPO DE REQUERIMIENTO | I1: TIPO DE RECLAMO | J1: RECLAMO FUNDAMENTADO | K1: RESPONSABLE DE LA RESPUESTA | L1: ESTATUS DE GESTIÓN | M1: FECHA DE RESOLUCION | N1: DIAS TOTALES | O1: DENTRO DEL ANS ESTABLECIDO | P1: OBS | Q1: CON RESPUESTA | R1: RESPONSABLE | S1: FECHA | T1: ANS | U1: CRUCE BASE TOTAL | V1: FECHA DE RESPUESTA | W1: obs
A2: 45712 | B2: CORREO | C2: 7218366 | D2: GLADYS PATRICIA GUTIERREZ VELEZMORO | G2: RIMAC VIP//PROGRAMA CRONICOS REUMATOLOGIA//GLADYS PATRICIA GUTIERREZ VELEZMORO | H2: RECLAMOS | I2: DEMORA COORDINACIÓN DE CITAS | J2: SI | K2: Viva 1 A | L2: SIN RESPUESTA | M2: 45742 | N2: 19 | P2: si | Q2: SI | R2: Maribel | S2: 45749 | T2: Finalizado | U2: =VLOOKUP(C2,'DATA CORREO'!G:W,17,0) -> CERRADA | V2: =VLOOKUP(C2,'DATA CORREO'!G:V,16,0) -> 45749
A3: 45716 | B3: CORREO | C3: 8287353 | D3: LEON MAGNO SANCHEZ QUINTANILLA | G3: programa cuídate / LEON MAGNO SANCHEZ QUINTANILLA | H3: RECLAMOS | I3: DEMORA ENTREGA DE MEDICAMENTOS | J3: SI | K3: Viva 1 A | L3: RESPONDIDO | M3: 45742 | N3: 19 | P3: data rimac x | Q3: SI | R3: Maribel | S3: 45749 | T3: Finalizado | U3: =VLOOKUP(C3,'DATA CORREO'!G:W,17,0) -> CERRADA | V3: =VLOOKUP(C3,'DATA CORREO'!G:V,16,0) -> 45749
A4: 45716 | B4: CORREO | C4: 3684166 | D4: DIEGO VILLANUEVA RUIZ | G4: INSCRIPCION PARA EL PROGRAMA CUIDATE PX DIEGO VILLANUEVA RUIZ | H4: SOLICITUDES | I4: DEMANDA INDUCIDA | J4: SI | K4: Viva 1 A | L4: SIN RESPUESTA | M4: 45742 | N4: 19 | P4: data rimac x | Q4: SI | R4: Chrismerly | S4: 45750 | T4: Finalizado | U4: =VLOOKUP(C4,'DATA CORREO'!G:W,17,0) -> CERRADA | V4: =VLOOKUP(C4,'DATA CORREO'!G:V,16,0) -> 45750
A5: 45716 | B5: CORREO | C5: 8783626 | D5: GIOVANNA MARIA LUZ VALEGA DURAND | G5: RIMAC VIP // CONSULTA PROGRAMA CUIDATE // GIOVANNA MARIA LUZ VALEGA DURAND// CLIENTE CRÍTICA | H5: RECLAMOS | I5: DEMORA COORDINACIÓN DE CITAS | J5: SI | K5: Viva 1 A | L5: SIN RESPUESTA | M5: 45742 | N5: 18 | P5: correo enviado | Q5: SI | R5: Gianina | S5: 45735 | T5: Finalizado | U5: =VLOOKUP(C5,'DATA CORREO'!G:W,17,0) -> CERRADA | V5: =VLOOKUP(C5,'DATA CORREO'!G:V,16,0) -> 45737
A6: 45716 | B6: CORREO | C6: 8249657 | D6: FARA NOEMI MIRANDA PACHECO DE CHOY | G6: PACIENTE DEL PROGRAMA CUIDATE PENDIENTE ENTREGA DE SUS MEDICAMENTOS /FARA NOEMI MIRANDA PACHECO DE CHOY DNI :08249657 | H6: RECLAMOS | I6: DEMORA ENTREGA DE MEDICAMENTOS | J6: SI | K6: Viva 1 A | L6: SIN RESPUESTA | M6: 45742 | N6: 17 | P6: correo enviado | Q6: SI | R6: Maribel | S6: 45747 | T6: Finalizado | U6: =VLOOKUP(C6,'DATA CORREO'!G:W,17,0) -> CERRADA | V6: =VLOOKUP(C6,'DATA CORREO'!G:V,16,0) -> 45747
A7: 45716 | B7: CORREO | C7: 44000062 | D7: LLAMOJA VICENTE DENNISE | G7: CUIDATE- PROGRAMA CRONICO | H7: RECLAMOS | I7: DEMORA TOMA DE TOMA DE MUESTRAS | J7: SI | K7: Viva 1 A | L7: SIN RESPUESTA | M7: 45742 | N7: 19 | P7: sin correo inicial | Q7: SI | R7: Chrismerly | S7: 45754 | T7: Finalizado | U7: =VLOOKUP(C7,'DATA CORREO'!G:W,17,0) -> CERRADA | V7: =VLOOKUP(C7,'DATA CORREO'!G:V,16,0) -> 45754
A8: 45719 | B8: CORREO | C8: 29561921 | D8: ALVAREZ MONGE LELIA | G8: REVISION ASEGURADO : ALVAREZ MONGE LELIA DNI : 29561921 - MINSUR | H8: RECLAMOS | I8: DEMORA COORDINACIÓN DE CITAS | J8: SI | K8: Viva 1 A | L8: RESPONDIDO | M8: 45742 | N8: 16 | P8: data rimac x | Q8: SI | R8: Maribel | S8: 45749 | T8: Finalizado | U8: =VLOOKUP(C8,'DATA CORREO'!G:W,17,0) -> CERRADA | V8: =VLOOKUP(C8,'DATA CORREO'!G:V,16,0) -> 45749
A9: 45720 | B9: CORREO | C9: 8243493 | D9: Talia Gianina Martínez de Arauzo | G9: Ingreso al programa Cuídate | H9: SOLICITUDES | I9: DEMANDA INDUCIDA | K9: Viva 1 A | L9: SIN RESPUESTA | M9: 45742 | N9: 19 | P9: correo enviado | Q9: SI | R9: Maribel | S9: 45748 | T9: Finalizado | U9: =VLOOKUP(C9,'DATA CORREO'!G:W,17,0) -> CERRADA | V9: =VLOOKUP(C9,'DATA CORREO'!G:V,16,0) -> 45748
A10: 45721 | B10: CORREO | C10: 77742062 | D10: EDGAR IGNACIO DE LA TORRE RODRIGUEZ | G10: PACIENTE DEL PROGRAMA CUIDATE /EDGAR IGNACIO DE LA TORRE RODRIGUEZ DNI :77742062 | H10: RECLAMOS | I10: DEMORA COORDINACIÓN DE CITAS | J10: SI | K10: Viva 1 A | L10: SIN RESPUESTA | M10: 45742 | N10: 16 | P10: correo enviado | Q10: SI | R10: Maribel | S10: 45748 | T10: Finalizado | U10: =VLOOKUP(C10,'DATA CORREO'!G:W,17,0) -> CERRADA | V10: =VLOOKUP(C10,'DATA CORREO'!G:V,16,0) -> 45748
A11: 45721 | B11: CORREO | D11: POTENCIALES AL PROGRAMA CUIDATE Y OTROS CRONICOS-SURA /RIESGO | G11: POTENCIALES AL PROGRAMA CUIDATE Y OTROS CRONICOS-SURA /RIESGO | H11: SOLICITUDES | I11: DEMANDA INDUCIDA | K11: Viva 1 A | L11: SIN RESPUESTA | M11: 45742 | N11: 23 | P11: data rimac x | Q11: SI | R11: Chrismerly | S11: 45754 | T11: Seguimiento | U11: SEGUIMIENTO | V11: 45754 | W11: Discriminado por usuarios, resuelto parcialmente
A12: 45721 | B12: CORREO | C12: 8268085 | D12: GARCIA CASTILLO NORA EMMA | G12: TALMA - EPS - ATENCION MEDICA - ASEG: GARCIA CASTILLO NORA EMMA | H12: RECLAMOS | I12: DEMORA ENTREGA DE MEDICAMENTOS | J12: SI | K12: Viva 1 A | L12: SIN RESPUESTA | M12: 45742 | N12: 16 | P12: correo enviado | Q12: SI | R12: Antonio | S12: 45726 | T12: Finalizado | U12: =VLOOKUP(C12,'DATA CORREO'!G:W,17,0) -> CERRADA | V12: =VLOOKUP(C12,'DATA CORREO'!G:V,16,0) -> 45726
A13: 45721 | B13: CORREO | C13: 7307988 | D13: CECILIA ESTHER CANALES ANICAMA | G13: PROGRAMA CRONICOS - Paciente - CECILIA ESTHER CANALES ANICAMA | H13: RECLAMOS | I13: DEMORA COORDINACIÓN DE CITAS | K13: Viva 1 A | L13: SIN RESPUESTA | M13: 45742 | N13: 16 | P13: correo enviado | Q13: SI | R13: Maribel | S13: 45748 | T13: Finalizado | U13: =VLOOKUP(C13,'DATA CORREO'!G:W,17,0) -> CERRADA | V13: =VLOOKUP(C13,'DATA CORREO'!G:V,16,0) -> 45748
A14: 45721 | B14: CORREO | C14: 72182950 | D14: XIMENA SOFIA DELGADILLO CABRERA | G14: XIMENA SOFIA DELGADILLO CABRERA-72182950 | H14: SOLICITUDES | I14: DEMANDA INDUCIDA | K14: Viva 1 A | L14: SIN RESPUESTA | M14: 45742 | N14: 16 | P14: correo enviado | Q14: SI | R14: Kathy | S14: 45746 | T14: Finalizado | U14: =VLOOKUP(C14,'DATA CORREO'!G:W,17,0) -> CERRADA | V14: =VLOOKUP(C14,'DATA CORREO'!G:V,16,0) -> 45746
A15: 45722 | B15: CORREO | C15: 9876517 | D15: Victor Edgar Solis Plaza | G15: REFINERIA LA PAMPILLA / EPS N° E0001009 / ASEGURADO: Victor Edgar Solis Plaza / RECLAMO URGENTE | I15: NO ACEPTA COPAGOS | K15: Viva 1 A | L15: SIN RESPUESTA | M15: 45742 | N15: 15 | P15: respondido 30/3 | Q15: SI | R15: Chrismerly | S15: 45750 | T15: Finalizado | U15: =VLOOKUP(C15,'DATA CORREO'!G:W,17,0) -> CERRADA | V15: =VLOOKUP(C15,'DATA CORREO'!G:V,16,0) -> 45750 | W15: No se evidencia correo de respuesta al asegurador, ultimo correo de seguimiento del dr fredy el 3/4/2025 Freddy Garzón<fgarzon@viva1a.com.pe> ​ Gianina Jessica Sigueña Aldana ​ ​ Antonio Torres Olivas; ​ Maximo Alfaro Andrade; ​ Chrismerly Abigail Huaranca López ​ saludos este correo avala la entrega del concentrador de oxigeno al paciente solis Gianina sobre el correo Principal demos respuesta a la EPS para que ejecuten el pago gracias
A16: 45723 | B16: CORREO | C16: 3506981 | D16: Juan Manuel Rivas Castillo | G16: DERIVACION MDC A CUIDATE | H16: SOLICITUDES | I16: DEMANDA INDUCIDA | K16: Viva 1 A | L16: SIN RESPUESTA | M16: 45742 | N16: 8 | P16: correo enviado | Q16: SI | R16: Maribel | S16: 45748 | T16: Finalizado | U16: =VLOOKUP(C16,'DATA CORREO'!G:W,17,0) -> CERRADA | V16: =VLOOKUP(C16,'DATA CORREO'!G:V,16,0) -> 45733
A17: 45723 | B17: CORREO | C17: 2009433 | D17: ESMEIDA ODILA SUBERO DE HERNANDEZ | G17: RIMAC VIP // CONSULTA ENVIO DE MEDICAMENTOS // PROGRAMA CRONICO // ESMEIDA ODILA SUBERO DE HERNANDEZ | H17: RECLAMOS | I17: DEMORA ENTREGA DE MEDICAMENTOS | J17: SI | K17: Viva 1 A | L17: SIN RESPUESTA | M17: 45734 | N17: 8 | P17: respondido | Q17: SI | R17: Chrismerly | S17: 45750 | T17: Finalizado | U17: =VLOOKUP(C17,'DATA CORREO'!G:W,17,0) -> CERRADA | V17: =VLOOKUP(C17,'DATA CORREO'!G:V,16,0) -> 45750 | W17: Hay un caso de este paciente resuelto en el correo con el asunto: URGENTE PACIENTE Programa Cuídate SUBERO DE HERNANDEZ ESMEIDA ODILA Gianina Jessica Sigueña Aldana ​ CUI_Guissela Bedon Espinoza <xt10033@rimac.com.pe>; ​y 3 más ​ ​ ​ ​y 5 más ​ ​ ​ ​ ​ Estimada Guissela, buen día: En referencia a lo solicitado, se valida que efectivamente nuestra mutua paciente ha tenido consulta efectiva con el Dr. Moncada el día 17/2/24. Se valida con farmacia la dispensación conforme de los medicamentos indicados en RM. Cabe resaltar que la Sra. Subero indica en base de migración programa RCV; sin embargo, no cuenta con dx acorde al programa indicado. Para tranquilidad de cara a la experiencia del usuario, nuestro médico de piso realizará una llamada para validar los medicamentos que indican se encuentran faltantes. Se reportará luego de que la paciente responda. Saludos Cordiales,
A18: 45726 | B18: CORREO | C18: 29222292 | D18: PACHECO TEJADA JORGE ADALBERTO | G18: UCSP// PROGRAMA CUIDATE// INCONVENIENTES DE ENTREGA DE MEDICAMENTOS// PACHECO TEJADA JORGE ADALBERTO | H18: RECLAMOS | I18: DEMORA COORDINACIÓN DE CITAS | J18: SI | K18: Viva 1 A | L18: SIN RESPUESTA | M18: 45742 | N18: 7 | P18: correo enviado | Q18: SI | R18: Maribel | S18: 45750 | T18: Finalizado | U18: =VLOOKUP(C18,'DATA CORREO'!G:W,17,0) -> CERRADA | V18: =VLOOKUP(C18,'DATA CORREO'!G:V,16,0) -> 45750
A19: 45726 | B19: CORREO | C19: 8170776 | D19: NILTON HERMAN JIMENEZ ROSALES | G19: CONTINUDAD DE TERAPIAS FISICAS USUARIO NILTON HERMAN JIMENEZ ROSALES DNI:08170776 -DIAMANTE | H19: SOLICITUDES | I19: DERIVACIÓN ESPECIALIDADES | K19: Viva 1 A | L19: SIN RESPUESTA | M19: 45742 | N19: 7 | P19: no se ubica el correo | Q19: SI | R19: Chrismerly | S19: 45751 | T19: Seguimiento | U19: =VLOOKUP(C19,'DATA CORREO'!G:W,17,0) -> CERRADA | V19: =VLOOKUP(C19,'DATA CORREO'!G:V,16,0) -> 45751 | W19: No se encuentra en correo
A20: 45726 | B20: CORREO | C20: 44841514 | D20: URGENTE // RIMAC VIP // CARINA MIRANDA LAZO // DNI 44841514 // CONSULTA PROVEEDOR REEMPLAZO STARVITAL | H20: RECLAMOS | I20: DEMORA ENTREGA DE MEDICAMENTOS | J20: SI | K20: Viva 1 A | L20: SIN RESPUESTA | M20: 45742 | N20: 13 | P20: correo enviado | Q20: SI | R20: Maribel | S20: 45748 | T20: Finalizado | U20: =VLOOKUP(C20,'DATA CORREO'!G:W,17,0) -> CERRADA | V20: =VLOOKUP(C20,'DATA CORREO'!G:V,16,0) -> 45748
A21: 45726 | B21: CORREO | C21: 72154157 | D21: FIORELLA CRISEL VERGARA OLIVO | G21: CONDICIONES DE CONTRATO CON EL PRESTADOR PARA ATENCION A PACIENTE EN MENCION | H21: RECLAMOS | I21: INSATISFACCION POR ATENCIÓN MEDICA | J21: SI | K21: Viva 1 A | L21: SIN RESPUESTA | M21: 45742 | N21: 8 | P21: se respondio fecha 11/3 | Q21: SI | R21: Chrismerly | S21: 45751 | T21: Finalizado | U21: =VLOOKUP(C21,'DATA CORREO'!G:W,17,0) -> CERRADA | V21: =VLOOKUP(C21,'DATA CORREO'!G:V,16,0) -> 45751 | W21: No se evidencia respuesta al asegurador, fue reenviado al correo de quejasyreclamos hoy por chrismerly, ultimo correo de seguimiento: De: Freddy Garzón <fgarzon@viva1a.com.pe> Enviado: martes, 11 de marzo de 2025 16:07 Para: Admision Rimac <admisionrimac@viva1a.com.pe>; Gianina Jessica Sigueña Aldana <gsiguenas@viva1a.com.pe> Cc: Julio Marco Inocencio Pereyra <jinocencio@viva1a.com.pe>; Chrismerly Abigail Huaranca López <chuaranca@viva1a.com.pe> Asunto: RV: CONDICIONES DE CONTRATO CON EL PRESTADOR PARA ATENCION A PACIENTE EN MENCION saludos en relación al caso favor programar las atenciones presenciales y cuando la paciente lo requiera se puede ofrecer tele consulta o atención en sede laboratorios según protocolo. gracias
A22: 45726 | B22: CORREO | C22: 44841514 | D22: CARINA MIRANDA LAZO | G22: URGENTE // RIMAC VIP // CARINA MIRANDA LAZO // DNI 44841514 // CONSULTA PROVEEDOR REEMPLAZO STARVITAL | H22: RECLAMOS | I22: DEMORA ENTREGA DE MEDICAMENTOS | J22: SI | K22: Viva 1 A | L22: SIN RESPUESTA | M22: 45742 | N22: 13 | P22: correo enviado | Q22: SI | R22: Maribel | S22: 45748 | T22: Finalizado | U22: =VLOOKUP(C22,'DATA CORREO'!G:W,17,0) -> CERRADA | V22: =VLOOKUP(C22,'DATA CORREO'!G:V,16,0) -> 45748
A23: 45727 | B23: CORREO | C23: 74839971 | D23: ALEJANDRO MIGUEL FIELD HERRERA | G23: programa cuidate - ALEJANDRO MIGUEL FIELD HERRERA | H23: SOLICITUDES | I23: DEMANDA INDUCIDA | K23: Viva 1 A | L23: SIN RESPUESTA | M23: 45742 | N23: 9 | P23: correo enviado | Q23: SI | R23: Maribel | S23: 45748 | T23: Finalizado | U23: =VLOOKUP(C23,'DATA CORREO'!G:W,17,0) -> CERRADA | V23: =VLOOKUP(C23,'DATA CORREO'!G:V,16,0) -> 45748
A24: 45727 | B24: CORREO | C24: 72845505 | D24: MORALES HERNANDEZ FABRICIO ANDRE | G24: URGENTE !!!CONFIRMACIÓN DE ATENCIÓN DE USUARIO MORALES HERNANDEZ FABRICIO ANDRE DNI 72845505-REDONDOS | H24: RECLAMOS | I24: DEMORA COORDINACIÓN DE CITAS | J24: SI | K24: Viva 1 A | L24: SIN RESPUESTA | M24: 45742 | N24: 9 | P24: no | Q24: SI | R24: Chrismerly | S24: 45751 | T24: Finalizado | U24: =VLOOKUP(C24,'DATA CORREO'!G:W,17,0) -> CERRADA | V24: =VLOOKUP(C24,'DATA CORREO'!G:V,16,0) -> 45751 | W24: No se encuentra en correo, llego en esta base
A25: 45728 | B25: CORREO | C25: 72844745 | D25: Diego Alejandro Vasquez Iglesias | G25: ADMINISTRADORA JOCKEY - programa Cuidate Rimac // Aseg. Vasquez Iglesias Diego // EPS - E0003570 | H25: RECLAMOS | I25: DEMORA ENTREGA DE MEDICAMENTOS | J25: SI | K25: Viva 1 A | L25: SIN RESPUESTA | M25: 45735 | N25: 5 | P25: respondido 31/3 | Q25: SI | R25: Kathy | S25: 45747 | T25: Finalizado | U25: =VLOOKUP(C25,'DATA CORREO'!G:W,17,0) -> CERRADA | V25: =VLOOKUP(C25,'DATA CORREO'!G:V,16,0) -> 45747
A26: 45728 | B26: CORREO | C26: 6698348 | D26: DANIEL AUGUSTO REYES HUERTA | G26: RIMAC VIP / REGISTRO PARA PROGRAMA CUIDATE /DANIEL AUGUSTO REYES HUERTA | H26: SOLICITUDES | I26: DEMANDA INDUCIDA | K26: Viva 1 A | L26: SIN RESPUESTA | M26: 45742 | N26: 10 | P26: correo enviado | Q26: SI | R26: Gianina | S26: 45741 | T26: Finalizado | U26: =VLOOKUP(C26,'DATA CORREO'!G:W,17,0) -> TRASLADADA | V26: =VLOOKUP(C26,'DATA CORREO'!G:V,16,0) -> 45741
A27: 45728 | B27: CORREO | C27: 7805048 | D27: JAVIER CARLOS SUAREZ HELFER | G27: INSCRIPCION PROGRAMA CUIDATE / HIPERTENSION ARTERIAL / JAVIER CARLOS SUAREZ HELFER | H27: RECLAMOS | I27: DEMORA COORDINACIÓN DE CITAS | J27: SI | K27: Viva 1 A | L27: SIN RESPUESTA | M27: 45742 | N27: 9 | P27: correo enviado | Q27: SI | R27: Maribel | S27: 45748 | T27: Finalizado | U27: =VLOOKUP(C27,'DATA CORREO'!G:W,17,0) -> CERRADA | V27: =VLOOKUP(C27,'DATA CORREO'!G:V,16,0) -> 45748
A28: 45728 | B28: CORREO | C28: 44852752 | D28: Elizabeth Elena Santos Rudas | G28: Urgente solicitud de ingreso: Programa cuidate asma - Sra. Elizabeth Santos Rudas | H28: SOLICITUDES | I28: DEMANDA INDUCIDA | K28: Viva 1 A | L28: SIN RESPUESTA | M28: 45742 | N28: 10 | P28: no | Q28: SI | R28: Chrismerly | S28: 45751 | T28: Finalizado | U28: =VLOOKUP(C28,'DATA CORREO'!G:W,17,0) -> CERRADA | V28: =VLOOKUP(C28,'DATA CORREO'!G:V,16,0) -> 45751 | W28: No se encuentra en correo, llego en esta base
A29: 45728 | B29: CORREO | C29: 7731756 | D29: La Serna Garcia Laura | G29: QUEJA VIVA 1A / CONSULTA / URGENTE PAGO DE MEDICAMENTO PROGRAMA CUIDATE - RIMAC // ASOC. BENEFICA PRISMA // Seguimiento ZL | H29: RECLAMOS | I29: DEMORA ENTREGA DE MEDICAMENTOS | K29: Viva 1 A | L29: SIN RESPUESTA | M29: 45742 | N29: 9 | P29: si | Q29: SI | R29: Chrismerly | S29: 45751 | T29: Finalizado | U29: =VLOOKUP(C29,'DATA CORREO'!G:W,17,0) -> CERRADA | V29: =VLOOKUP(C29,'DATA CORREO'!G:V,16,0) -> 45749 | W29: Respuesta enviada por maribel el 2/4/2025
A30: 45728 | B30: CORREO | C30: 6040784 | D30: JULIO RAFAEL MARTIN CAMPOS | G30: RIMAC VIP // JULIO RAFAEL MARTIN CAMPOS | H30: RECLAMOS | I30: DEMORA COORDINACIÓN DE CITAS | J30: SI | K30: Viva 1 A | L30: SIN RESPUESTA | M30: 45742 | N30: 11 | P30: si | Q30: SI | R30: Maribel | S30: 45718 | T30: Finalizado | U30: =VLOOKUP(C30,'DATA CORREO'!G:W,17,0) -> CERRADA | V30: =VLOOKUP(C30,'DATA CORREO'!G:V,16,0) -> 45749
A31: 45728 | B31: CORREO | C31: 42413293 | D31: Julissa Fabiola Gómez Paz | G31: PROGRAMA CUIDATE// EPS RIMAC//Julissa Fabiola Gómez Paz//Hipertensión arterial | H31: RECLAMOS | I31: DEMORA COORDINACIÓN DE CITAS | J31: SI | K31: Viva 1 A | L31: SIN RESPUESTA | M31: 45742 | N31: 11 | P31: no | Q31: SI | R31: Chrismerly | S31: 45750 | T31: Finalizado | U31: =VLOOKUP(C31,'DATA CORREO'!G:W,17,0) -> CERRADA | V31: =VLOOKUP(C31,'DATA CORREO'!G:V,16,0) -> 45751 | W31: No se encuentra en correo, llego en esta base
A32: 45728 | B32: CORREO | C32: 46674191 | D32: CASO CRITICO VERONICA ANDREA TAMARIZ VALENTIN - 46674191 | G32: CASO CRITICO VERONICA ANDREA TAMARIZ VALENTIN - 46674191 | H32: RECLAMOS | I32: DEMORA COORDINACIÓN DE CITAS | J32: SI | K32: Viva 1 A | L32: SIN RESPUESTA | M32: 45742 | N32: 11 | P32: si | Q32: SI | R32: Maribel | S32: 45718 | T32: Finalizado | U32: =VLOOKUP(C32,'DATA CORREO'!G:W,17,0) -> CERRADA | V32: =VLOOKUP(C32,'DATA CORREO'!G:V,16,0) -> 45749
A33: 45729 | B33: CORREO | C33: 25616130 | D33: PAULA ZARELA MATTA VDA DE RAMOS | G33: RECLAMO 25-SBS013610 // PAULA ZARELA MATTA VDA DE RAMOS | H33: RECLAMOS | I33: INSATISFACCION POR ATENCIÓN MEDICA | J33: SI | K33: Viva 1 A | L33: SIN RESPUESTA | M33: 45742 | N33: 11 | P33: no | Q33: NO | T33: Seguimiento | U33: =VLOOKUP(C33,'DATA CORREO'!G:W,17,0) -> CERRADA | V33: =VLOOKUP(C33,'DATA CORREO'!G:V,16,0) -> 45748 | W33: Resuelto en base oriana ok
A34: 45729 | B34: CORREO | D34: PACIENTES CRONICOS - GRUPO CARVAJAL - E0037430, E0037415, E0037416, E0037420 | G34: PACIENTES CRONICOS - GRUPO CARVAJAL - E0037430, E0037415, E0037416, E0037420 | H34: SOLICITUDES | I34: DEMANDA INDUCIDA | J34: SI | K34: Viva 1 A | L34: SIN RESPUESTA | M34: 45742 | N34: 11 | P34: no | Q34: SI | R34: Chrismerly | S34: 45751 | T34: Seguimiento | U34: SEGUIMIENTO | V34: 45751 | W34: Discriminado por usuarios, resuelto parcialmente
A35: 45729 | B35: CORREO | C35: 8185495 | D35: PATRICIA OCHOA LUBINOFF | G35: URGENTE ENTREGA DE MEDICINAS // GALLAGHER : PLAN EPS (PROGRAMA CRONICOS HIPOTIROIDISMO): PATRICIA OCHOA LUBINOFF (reclamo) | H35: RECLAMOS | I35: DEMORA COORDINACIÓN DE CITAS | J35: SI | K35: Viva 1 A | L35: SIN RESPUESTA | M35: 45742 | N35: 11 | P35: SI | Q35: SI | R35: Maribel | S35: 45718 | T35: Finalizado | U35: =VLOOKUP(C35,'DATA CORREO'!G:W,17,0) -> CERRADA | V35: =VLOOKUP(C35,'DATA CORREO'!G:V,16,0) -> 45749
A36: 45729 | B36: CORREO | C36: 10060304 | D36: Glicerio Camino Siles | G36: Programa Cuidate | H36: SOLICITUDES | I36: DEMANDA INDUCIDA | J36: SI | K36: Viva 1 A | L36: SIN RESPUESTA | M36: 45742 | N36: 11 | P36: no | Q36: SI | R36: Chrismerly | S36: 45751 | T36: Finalizado | U36: =VLOOKUP(C36,'DATA CORREO'!G:W,17,0) -> CERRADA | V36: =VLOOKUP(C36,'DATA CORREO'!G:V,16,0) -> 45751 | W36: No tiene respuesta
A37: 45730 | B37: CORREO | D37: INVITACION PACIENTES CRONICOS - HORTUS | G37: INVITACION PACIENTES CRONICOS - HORTUS | H37: SOLICITUDES | I37: DEMANDA INDUCIDA | K37: Viva 1 A | L37: SIN RESPUESTA | M37: 45742 | N37: 11 | P37: no | Q37: SI | R37: Maribel | S37: 45750 | T37: Seguimiento | U37: SEGUIMIENTO | V37: 45750 | W37: Son 6 pacientes, se asignaron 4 pendiente 2 que no se ha logrado comunicación
A38: 45730 | B38: CORREO | D38: URGENTE : Programa PPC / URGENTE / EMPRESA SAPET / ACTUALIZACION/ LISTADO PACIENTE CRONICOS | G38: URGENTE : Programa PPC / URGENTE / EMPRESA SAPET / ACTUALIZACION | H38: SOLICITUDES | I38: INORMACIÓN PROCESOS | J38: SI | K38: Viva 1 A | L38: SIN RESPUESTA | M38: 45742 | N38: 12 | P38: NO | Q38: SI | R38: Chrismerly | S38: 45751 | T38: seguimiento | U38: SEGUIMIENTO | V38: 45751 | W38: Discriminado por usuarios, resuelto parcialmente
A39: 45730 | B39: CORREO | C39: 7731756 | D39: La Serna Garcia Laura | G39: QUEJA CHEQUEO PREVENTIVO //B CONSULTA / QUEJA ATENCION EN LA EPS // ASOC. BENEFICA PRISMA . Aseg. Laura Laserna // Seguimiento ZL | H39: RECLAMOS | I39: DEMORA COORDINACIÓN DE CITAS | J39: SI | K39: Viva 1 A | L39: SIN RESPUESTA | M39: 45742 | N39: 12 | P39: correo enviado | Q39: SI | R39: Maribel | S39: 45751 | T39: Finalizado | U39: =VLOOKUP(C39,'DATA CORREO'!G:W,17,0) -> CERRADA | V39: =VLOOKUP(C39,'DATA CORREO'!G:V,16,0) -> 45749
A40: 45730 | B40: CORREO | C40: 25639731 | D40: CONTRERA SOLARI ROSARIO | G40: URGENTE - COORDINACION PENDIENTE - ANALISIS - KATHERINE OCHOA - DNI: 25639731 | H40: RECLAMOS | I40: DEMORA TOMA DE TOMA DE MUESTRAS | J40: SI | K40: Viva 1 A | L40: SIN RESPUESTA | M40: 45735 | N40: 8 | P40: correo enviado | Q40: SI | R40: Maribel | S40: 45747 | T40: Finalizado | U40: =VLOOKUP(C40,'DATA CORREO'!G:W,17,0) -> CERRADA | V40: =VLOOKUP(C40,'DATA CORREO'!G:V,16,0) -> 45747
...

Sheet pendientes rimac 2506
A1: FECHA DE INGRESO DEL REQUERIMIENTO | B1: CANAL | C1: DNI | D1: NOMBRES Y APELLIDOS | E1: RUC CONTRATANTE | F1: DESCRIPCIÓN DE CONTRATANTE | G1: TENOR DEL CORREO | H1: TIPO DE REQUERIMIENTO | I1: TIPO DE RECLAMO | J1: RECLAMO FUNDAMENTADO | K1: RESPONSABLE DE LA RESPUESTA | L1: ESTATUS DE GESTIÓN | M1: FECHA DE RESOLUCION | N1: DIAS TOTALES | O1: OBSERVACION | P1: cruce base reclamos
A2: 45743 | B2: CORREO | C2: 1 | D2: UCSM // PROGRAMA OTRAS ENFERMEDADES/ PROVEEDOR: VIVA A1 | G2: UCSM // PROGRAMA OTRAS ENFERMEDADES/ PROVEEDOR: VIVA A1 | H2: RECLAMOS | I2: INSATISFACCION POR ATENCIÓN MEDICA | K2: Viva 1 A | L2: SIN RESPUESTA | M2: 45833 | N2: 65 | P2: =VLOOKUP(C2,'DATA CORREO'!G:W,17,0) -> #N/A
A3: 45747 | B3: CORREO | C3: 7636877 | D3: MARIA DEL CARMEN CARRASCO PANTA | G3: RECLAMO 25-EPS002484 // MARIA DEL CARMEN CARRASCO PANTA | H3: RECLAMOS | I3: DEMORA COORDINACIÓN DE CITAS | K3: Viva 1 A | L3: SIN RESPUESTA | M3: 45833 | N3: 63 | P3: =VLOOKUP(C3,'DATA CORREO'!G:W,17,0) -> CERRADA
A4: 45748 | B4: CORREO | C4: 10004424 | D4: JOSE HERNAN LATORRE DIAZ | G4: URGENTE // HOSPITALIZACION EN CASA | H4: SOLICITUDES | I4: DEMANDA INDUCIDA | K4: Viva 1 A | L4: SIN RESPUESTA | M4: 45833 | N4: 62 | P4: =VLOOKUP(C4,'DATA CORREO'!G:W,17,0) -> CERRADA
A5: 45751 | B5: CORREO | C5: 29702122 | D5: CÁCERES CHALCO HIPOLITO. | G5: INGRESO RCV CONTINUADOR ANGLO AMERICAM CACERES CHALCO HIPOLITO DNI: 29702122 | H5: SOLICITUDES | I5: DEMANDA INDUCIDA | K5: Viva 1 A | L5: SIN RESPUESTA | M5: 45833 | N5: 59 | P5: =VLOOKUP(C5,'DATA CORREO'!G:W,17,0) -> CERRADA
A6: 45756 | B6: CORREO | C6: 74334143 | D6: MICHAEL ANDERSON URIARTE LEON | G6: MEDICINAS PENDIENTES - MICHAEL ANDERSON URIARTE LEON - dni 74334143 | H6: RECLAMOS | I6: DEMORA ENTREGA DE MEDICAMENTOS | K6: Viva 1 A | L6: SIN RESPUESTA | M6: 45833 | N6: 56 | P6: =VLOOKUP(C6,'DATA CORREO'!G:W,17,0) -> CERRADA
A7: 45758 | B7: CORREO | C7: 46036087 | D7: SALVATIERRA MELGAREJO JOHN ANDERSSON | G7: INGRESO AL PROGRAMA CUIDATE - SALVATIERRA MELGAREJO JOHN ANDERSSON - EPS CUIDA DIGITAL S.A.C E0028227 | H7: SOLICITUDES | I7: DEMANDA INDUCIDA | K7: Viva 1 A | L7: SIN RESPUESTA | M7: 45833 | N7: 54 | P7: =VLOOKUP(C7,'DATA CORREO'!G:W,17,0) -> CERRADA
A8: 45757 | B8: CORREO | C8: 72844745 | D8: Diego Alejandro Vasquez Iglesias | G8: ADMINISTRADORA JOCKEY - programa Cuidate Rimac // Aseg. Vasquez Iglesias Diego // EPS - E0003570 | H8: RECLAMOS | I8: DEMORA TOMA DE TOMA DE MUESTRAS | J8: SI | K8: Viva 1 A | L8: SIN RESPUESTA | M8: 45833 | N8: 55 | P8: =VLOOKUP(C8,'DATA CORREO'!G:W,17,0) -> CERRADA
A9: 45776 | B9: CORREO | C9: 8224705 | D9: RUBINI SUITO MARIO | G9: Paciente: MARIO RUBINI SUITO | H9: SOLICITUDES | I9: DEMANDA INDUCIDA | K9: Viva 1 A | L9: SIN RESPUESTA | M9: 45833 | N9: 42 | P9: =VLOOKUP(C9,'DATA CORREO'!G:W,17,0) -> CERRADA
A10: 45769 | B10: CORREO | C10: 9309622 | D10: RAUL ANTONIO MEJIA RAMIREZ | G10: CONFIRMAR INSCRIPCION PROGRAMA CUIDATE - RAUL ANTONIO MEJIA RAMIREZ DNI 09309622 | H10: RECLAMOS | I10: DEMORA TOMA DE TOMA DE MUESTRAS | K10: Viva 1 A | L10: SIN RESPUESTA | M10: 45833 | N10: 47 | P10: =VLOOKUP(C10,'DATA CORREO'!G:W,17,0) -> CERRADA
A11: 45779 | B11: CORREO | C11: 7879761 | D11: CARMEN YSABEL DENEGRI MORALES | G11: CARMEN YSABEL DENEGRI MORALES/Dni: 07879761/póliza: E0018055 | H11: RECLAMOS | I11: DEMORA ENTREGA DE MEDICAMENTOS | K11: Viva 1 A | L11: SIN RESPUESTA | M11: 45833 | N11: 39 | P11: =VLOOKUP(C11,'DATA CORREO'!G:W,17,0) -> CERRADA
A12: 45749 | B12: CORREO | C12: 2869403 | D12: GARCÍA SÁNCHEZ RAFAEL GUSTAVO | G12: URGENTE Gestión Programa de Pacientes Crónicos / EMPRESA SAPET / URGENT | H12: RECLAMOS | I12: DEMORA ENTREGA DE MEDICAMENTOS | K12: Viva 1 A | L12: SIN RESPUESTA | M12: 45833 | N12: 61 | P12: =VLOOKUP(C12,'DATA CORREO'!G:W,17,0) -> CERRADA
A13: 45749 | B13: CORREO | C13: 23656818 | D13: MENESES SERPA ANGELINO FORTUNATO | G13: RIMAC VIP//INSCRIPCIÓN PROGRAMA CUIDATE// ANGELINO FORTUNATO MENESES SERPA | H13: SOLICITUDES | I13: DEMANDA INDUCIDA | K13: Viva 1 A | L13: SIN RESPUESTA | M13: 45833 | N13: 61 | P13: =VLOOKUP(C13,'DATA CORREO'!G:W,17,0) -> CERRADA
A14: 45779 | B14: CORREO | C14: 9437292 | D14: ALFREDO CARLOS VALDIVIA DEL ALCAZAR I | G14: Envio orden de Analisis | H14: SOLICITUDES | I14: DEMORA TOMA DE TOMA DE MUESTRAS | K14: Viva 1 A | L14: SIN RESPUESTA | M14: 45833 | N14: 39 | P14: =VLOOKUP(C14,'DATA CORREO'!G:W,17,0) -> CERRADA
A15: 45779 | B15: CORREO | C15: 71119014 | D15: RAMON DIAZ DIANA MARLIZ | G15: OTROS CRONICOS//ARTRITIS REMATOIDE//INRETAIL | H15: RECLAMOS | I15: DEMORA TOMA DE TOMA DE MUESTRAS | K15: Viva 1 A | L15: SIN RESPUESTA | M15: 45833 | N15: 39 | P15: =VLOOKUP(C15,'DATA CORREO'!G:W,17,0) -> CERRADA | X15: 1575
A16: 45779 | B16: CORREO | C16: 7727653 | D16: OSCAR MARCIAL VELIT CASAS | G16: RIMAC VIP/ INSCRIPCION AL PROGRAMA OSCAR MARCIAL VELIT CASAS DNI 07727653 | H16: SOLICITUDES | I16: DEMANDA INDUCIDA | K16: Viva 1 A | L16: SIN RESPUESTA | M16: 45833 | N16: 39 | P16: =VLOOKUP(C16,'DATA CORREO'!G:W,17,0) -> TRASLADADA
A17: 45779 | B17: CORREO | C17: 1 | D17: GERMAN ROLANDO DE LA CRUZ RAMIREZ | G17: CUIDATE - DX POLINEUROPATIA // GERMAN ROLANDO DE LA CRUZ RAMIREZ DM-HTA | H17: SOLICITUDES | I17: DEMANDA INDUCIDA | K17: Viva 1 A | L17: SIN RESPUESTA | M17: 45833 | N17: 39 | P17: =VLOOKUP(C17,'DATA CORREO'!G:W,17,0) -> #N/A
A18: 45783 | B18: CORREO | C18: 1 | D18: URGENTE - Coordinaciones de entrega de medicamentos y cobertura de exámenes de laboratorio // CNCP - CRONICOS | G18: URGENTE - Coordinaciones de entrega de medicamentos y cobertura de exámenes de laboratorio // CNCP - CRONICOS | H18: RECLAMOS | I18: NO ACEPTA COPAGOS | K18: Viva 1 A | L18: SIN RESPUESTA | M18: 45833 | N18: 37 | P18: =VLOOKUP(C18,'DATA CORREO'!G:W,17,0) -> #N/A
A19: 45761 | B19: CORREO | C19: 6167823 | D19: DIAZ DE AVILES LUZ ANGELICA | G19: ESTATUS CLINICO USUARIA: DIAZ DE AVILES LUZ ANGELICA DNI 06167823 | H19: SOLICITUDES | I19: DEMANDA INDUCIDA | K19: Viva 1 A | L19: SIN RESPUESTA | M19: 45833 | N19: 53 | P19: =VLOOKUP(C19,'DATA CORREO'!G:W,17,0) -> CERRADA
A20: 45784 | B20: CORREO | C20: 78642647 | D20: LOREDO RAMIREZ MARCELO ALONSO | G20: URGENTE!!! DNI: 78642647 LOREDO RAMIREZ MARCELO ALONSO DM TIPO 1 | H20: RECLAMOS | I20: DEMORA ENTREGA DE MEDICAMENTOS | K20: Viva 1 A | L20: SIN RESPUESTA | M20: 45833 | N20: 36 | P20: =VLOOKUP(C20,'DATA CORREO'!G:W,17,0) -> CERRADA
A21: 45785 | B21: CORREO | C21: 1 | D21: *****URGENTE**** IASD - Pacientes con enfermedades crónicas | G21: *****URGENTE**** IASD - Pacientes con enfermedades crónicas | H21: SOLICITUDES | I21: DEMANDA INDUCIDA | K21: Viva 1 A | L21: SIN RESPUESTA | M21: 45833 | N21: 35 | P21: =VLOOKUP(C21,'DATA CORREO'!G:W,17,0) -> #N/A
A22: 45782 | B22: CORREO | C22: 1 | D22: RE: IASD - Pacientes con enfermedades crónicas | G22: RE: IASD - Pacientes con enfermedades crónicas | H22: SOLICITUDES | I22: DEMANDA INDUCIDA | K22: Viva 1 A | L22: SIN RESPUESTA | M22: 45833 | N22: 38 | P22: =VLOOKUP(C22,'DATA CORREO'!G:W,17,0) -> #N/A
A23: 45805 | B23: CORREO | C23: 6040784 | D23: JULIO RAFAEL MARTIN CAMPOS | G23: RIMAC VIP // JULIO RAFAEL MARTIN CAMPOS | H23: RECLAMOS | I23: DEMORA COORDINACIÓN DE CITAS | K23: Viva 1 A | L23: SIN RESPUESTA | M23: 45833 | N23: 21 | P23: =VLOOKUP(C23,'DATA CORREO'!G:W,17,0) -> CERRADA
A24: 45811 | B24: CORREO | C24: 562206 | D24: MOUSA JJ SANSOUR | G24: Paciente Mousa Sansour | H24: SOLICITUDES | I24: DEMANDA INDUCIDA | K24: Viva 1 A | L24: SIN RESPUESTA | M24: 45833 | N24: 17 | P24: =VLOOKUP(C24,'DATA CORREO'!G:W,17,0) -> CERRADA
A25: 45814 | B25: CORREO | C25: 8244905 | D25: FERNANDO ALFONSO CORDOVA PEREZ ALBELA | G25: RIMAC VIP // INCIDENCIA PROGRAMA CUIDATE // C: FERNANDO ALFONSO CORDOVA PEREZ ALBELA | H25: RECLAMOS | I25: DEMORA COORDINACIÓN DE CITAS | K25: Viva 1 A | L25: SIN RESPUESTA | M25: 45833 | N25: 14 | P25: =VLOOKUP(C25,'DATA CORREO'!G:W,17,0) -> CERRADA
A26: 45813 | B26: CORREO | C26: 3889684 | D26: HERRADA GALVEZ GINA | G26: SOLICITUDES PENDIENTES- Gestión Programa de Pacientes Crónicos / EMPRESA SAPET / URGENTE | H26: RECLAMOS | I26: DEMORA TOMA DE TOMA DE MUESTRAS | K26: Viva 1 A | L26: SIN RESPUESTA | M26: 45833 | N26: 15 | P26: =VLOOKUP(C26,'DATA CORREO'!G:W,17,0) -> CERRADA
A27: 45814 | B27: CORREO | C27: 22268777 | D27: LOYOLA VASQUEZ SARA PATRICIA | G27: RECLAMO 0025462603 / PROGRAMA CUIDATE / SARA PATRICIA LOYOLA VASQUEZ | H27: RECLAMOS | I27: DEMORA TOMA DE TOMA DE MUESTRAS | K27: Viva 1 A | L27: SIN RESPUESTA | M27: 45833 | N27: 14 | P27: =VLOOKUP(C27,'DATA CORREO'!G:W,17,0) -> CERRADA
... A29: 45814 | B29: CORREO | C29: 10808635 | D29: URBINA PEREZ SANDRA DANIELLA | G29: URGENTE!!!! URBINA PEREZ SANDRA DANIELLA DNI: 10808635 | H29: RECLAMOS | I29: INSATISFACCION POR ATENCIÓN MEDICA | K29: Viva 1 A | L29: SIN RESPUESTA | M29: 45833 | N29: 14 | P29: =VLOOKUP(C29,'DATA CORREO'!G:W,17,0) -> CERRADA
A30: 45812 | B30: CORREO | C30: 9437292(1) | D30: CARLOS VALDIVIA DEL ALCAZAR | G30: URGENTE ENTREGA DE MEDICINAS DEL PROGRAMA CUIDATE - ALFREDO CARLOS VALDIVIA DEL ALCAZAR CLIENTE: CORTE SUPERIOR DE JUSTICIA DE SAN MARTIN E0037244 | H30: RECLAMOS | I30: DEMORA ENTREGA DE MEDICAMENTOS | K30: Viva 1 A | L30: SIN RESPUESTA | M30: 45833 | N30: 16 | P30: =VLOOKUP(C30,'DATA CORREO'!G:W,17,0) -> CERRADA
A31: 45814 | B31: CORREO | C31: 29278513 | D31: VILLENA FARFAN PEDRO | G31: **URGENTE Revisar Problemas** RE: Programa Cuídate - EPS HORTUS | H31: SOLICITUDES | I31: DEMANDA INDUCIDA | K31: Viva 1 A | L31: SIN RESPUESTA | M31: 45833 | N31: 14 | P31: =VLOOKUP(C31,'DATA CORREO'!G:W,17,0) -> CERRADA
A32: 45819 | B32: CORREO | C32: 42161130 | D32: GUEVARA DELGADO LETICIA | G32: ****** URGENTE****INGRESO PROGRAMA CUIDATE // HORTUS | H32: SOLICITUDES | I32: DEMANDA INDUCIDA | K32: Viva 1 A | L32: SIN RESPUESTA | M32: 45833 | N32: 11 | P32: =VLOOKUP(C32,'DATA CORREO'!G:W,17,0) -> CERRADA
A33: 45804 | B33: CORREO | C33: 1 | D33: VILLAGARAY ESTRADA CARLOS ALBERTO | G33: URGENTE!!! INGRESO AL PROGRAMA-DIAMANTE TERAPIAS FISICAS VILLAGARAY ESTRADA CARLOS ALBERTO | H33: SOLICITUDES | I33: DEMANDA INDUCIDA | K33: Viva 1 A | L33: SIN RESPUESTA | M33: 45833 | N33: 22 | P33: =VLOOKUP(C33,'DATA CORREO'!G:W,17,0) -> #N/A
A34: 45819 | B34: CORREO | C34: 42161130(1) | D34: GUEVARA DELGADO LETICIA | G34: ****** URGENTE****INGRESO PROGRAMA CUIDATE // HORTUS | H34: RECLAMOS | I34: DEMORA ENTREGA DE MEDICAMENTOS | K34: Viva 1 A | L34: SIN RESPUESTA | M34: 45833 | N34: 11 | P34: =VLOOKUP(C34,'DATA CORREO'!G:W,17,0) -> CERRADA
A35: 45817 | B35: CORREO | C35: 8647598 | D35: GUILLERMO HURTADO SILVERA | G35: GUILLERMO HURTADO SILVERA//DNI:25755348//PÓLIZA E0001394 | H35: RECLAMOS | I35: DEMORA ENTREGA DE MEDICAMENTOS | K35: Viva 1 A | L35: SIN RESPUESTA | M35: 45833 | N35: 13 | P35: =VLOOKUP(C35,'DATA CORREO'!G:W,17,0) -> CERRADA
A36: 45803 | B36: CORREO | C36: 29278513 | D36: VILLENA FARFAN PEDRO | G36: *****URGENTE***** INGRESO CUIDATE HOURTUS | H36: RECLAMOS | I36: DEMORA COORDINACIÓN DE CITAS | K36: Viva 1 A | L36: SIN RESPUESTA | M36: 45833 | N36: 23 | P36: =VLOOKUP(C36,'DATA CORREO'!G:W,17,0) -> CERRADA
A37: 45826 | B37: CORREO | C37: 795889 | D37: MARIA LUISA VELASQUEZ | G37: NO CUENTO CON PRESTADOR | TOMA PARA LABORATORIO | TACNA | PX MARIA LUISA VELASQUEZ . | DNI 00795889 | H37: RECLAMOS | I37: DEMORA TOMA DE TOMA DE MUESTRAS | K37: Viva 1 A | L37: SIN RESPUESTA | M37: 45833 | N37: 6 | P37: =VLOOKUP(C37,'DATA CORREO'!G:W,17,0) -> CERRADA
A38: 45833 | B38: CORREO | C38: 7717416 | D38: NOEMI INES ROMAN OLAECHEA DE CARRILLO | G38: VALIDACIÓN INGRESO USUARIA NOEMI INES ROMAN OLAECHEA DE CARRILLO DNI 07717416 | H38: RECLAMOS | I38: INFORMACIÓN PROCESOS | K38: Viva 1 A | L38: EN GESTIÓN | M38: 45833 | N38: 1 | P38: =VLOOKUP(C38,'DATA CORREO'!G:W,17,0) -> TRASLADADA
A39: 45832 | B39: CORREO | C39: 8170776 | D39: NILTON HERNAN JIMENEZ ROSALES | G39: RIMAC | SOLICITUD DE CONSULTA MÉDICA ADICIONAL POR PROGRAMA DIAMANTE | ASEG. NILTON HERNAN JIMENEZ ROSALES | DNI 08170776 | H39: RECLAMOS | I39: NO ACEPTA COPAGOS | K39: Viva 1 A | L39: EN GESTIÓN | M39: 45833 | N39: 2 | P39: =VLOOKUP(C39,'DATA CORREO'!G:W,17,0) -> CERRADA
A40: 45825 | B40: CORREO | C40: 1 | D40: ANGLOAMERICAN | G40: ATENCIÓN DE PACIENTES CRÓNICOS | H40: RECLAMOS | I40: DEMORA ENTREGA DE MEDICAMENTOS | K40: Viva 1 A | L40: SIN RESPUESTA | M40: 45833 | N40: 7 | P40: =VLOOKUP(C40,'DATA CORREO'!G:W,17,0) -> #N/A
A41: 45831 | B41: CORREO | C41: 25-EPS003156 | D41: SARA ANGELICA CACERES LOPEZ | G41: RECLAMO 25-EPS003156 / PACIENTE : SARA ANGELICA CACERES LOPEZ / PROGRAMA CRONICO | H41: RECLAMOS | I41: DEMORA TOMA DE TOMA DE MUESTRAS | K41: Viva 1 A | L41: EN GESTIÓN | M41: 45833 | N41: 3 | P41: =VLOOKUP(C41,'DATA CORREO'!G:W,17,0) -> CERRADA
...

Sheet VISUAL
A1: INFORME RECLAMOS Y SOLICITUDES PERÚ
L2: ACTUALIZACIÓN | M2: 46009
D3: TOTAL RADICADAS | G3: RECLAMOS ACTIVAS | J3: RECLAMOS CERRADOS
D4: =GETPIVOTDATA("Cuenta de MOTIVO",TD__!$K$3) -> 1 | E4: =GETPIVOTDATA("Cuenta de MOTIVO2",TD__!$K$3) -> 1 | G4: =IFERROR(GETPIVOTDATA("Cuenta de MOTIVO",TD__!$K$3,"ESTADO FINAL","ACTIVA"),"0") -> 1 | H4: =IFERROR(GETPIVOTDATA("Cuenta de MOTIVO2",TD__!$K$3,"ESTADO FINAL","ACTIVA"),"0%") -> 1 | J4: =IFERROR(GETPIVOTDATA("Cuenta de MOTIVO",TD__!$K$3,"ESTADO FINAL","CERRADA"),"0") -> 0 | K4: =IFERROR(GETPIVOTDATA("Cuenta de MOTIVO2",TD__!$K$3,"ESTADO FINAL","CERRADA"),"0%") -> 0%
T9: 0.010893246
D66: PERIODO | E66: 202602

Sheet TD__
A3: Etiquetas de fila | B3: Cuenta de MOTIVO | F3: Etiquetas de fila | G3: Cuenta de MOTIVO | K3: Etiquetas de fila | L3: Cuenta de MOTIVO | M3: Cuenta de MOTIVO2 | O3: Etiquetas de fila | P3: Cuenta de MOTIVO | R3: Etiquetas de fila | S3: Cuenta de MOTIVO | U3: TIEMPO | V3: CANT
A4: INCONFORMIDAD CON LA ATENCION EN GENERAL | B4: 1 | F4: feb-19 | G4: 1 | K4: ACTIVA | L4: 1 | M4: 1 | O4: CUIDATE | P4: 1 | R4: 24 HORAS | S4: 1 | U4: 24 HORAS | V4: =IFERROR(VLOOKUP(U4,R:S,2,0),0) -> 1
A5: Total general | B5: 1 | F5: Total general | G5: 1 | K5: Total general | L5: 1 | M5: 1 | O5: Total general | P5: 1 | R5: Total general | S5: 1 | U5: 48 HORAS | V5: =IFERROR(VLOOKUP(U5,R:S,2,0),0) -> 0
U6: 72 HORAS | V6: =IFERROR(VLOOKUP(U6,R:S,2,0),0) -> 0
U7: 96 HORAS | V7: =IFERROR(VLOOKUP(U7,R:S,2,0),0) -> 0
U8: 120 HORAS | V8: =IFERROR(VLOOKUP(U8,R:S,2,0),0) -> 0
U9: 6 DIAS O MAS | V9: =IFERROR(VLOOKUP(U9,R:S,2,0),0) -> 0
U10: Total general | V10: =VLOOKUP(U10,R:S,2,0) -> 1

Sheet revision lorena
A1: TIPO DE DOCUMENTO | B1: DOCUMENTO | C1: PACIENTE | D1: DIRECCIÓN | E1: TELÉFONO | F1: CORREO | G1: RADICADO | H1: COD. SUBASTA | I1: PROCESO | J1: VIA DE RECEPCIÓN | K1: DESCRIPCIÓN QUEJA | L1: MOTIVO | M1: SERVICIO | N1: ESPECIALIDAD | O1: FECHA DEL INCIDENTE | P1: RESPUESTA | Q1: Comentarios | R1: FECHA DE RESPUESTA | S1: ESTADO
A2: DNI | B2: 8783626 | C2: GLORIA DURAND DE VALEGA | I2: SOLICITUD | J2: ASEGURADOR | K2: Me comenta la hija de la asegurada del detalle que todos los meses ha sido atendida en casa por Estar Vital, Empresa que como sabemos trabajaba con Rimac; sin embargo, para las atenciones del mes pasado febrero, al llamar para la cita respectiva le han indicado que ya no tienen convenio, por favor podrían informarme que Empresa será ahora quien otorgue el servicio. Asegurada: Gloria Durand de Valega. DNI 08783626. Tener en cuenta que, hasta enero 2025, la asegurada ha sido atendida mensualmente por *Estar Vital* quien la visitaba en casa, ya sea por un geriatra, medicina general o cardiólogo para revisión general y le otorgaban la medicina para la presión y el anticoagulante coberturado al 100% y se pagaba por el Hardal que es para el Parkinson. | L2: SOLICITUD DE CITA | M2: Atencion domiciliaria | N2: MEDICINA GENERAL | O2: 45720 | P2: REPROGRAMACION | Q2: SE AGENDA CITA CORRESPONDIENTE AL MES POR PROGRAMA (QUIERE DOMICILIARIA PARA EL SIGUIENTE MES ) | S2: ACTIVA
A3: DNI | B3: 7307988 | C3: CECILIA ESTHER CANALES ANICAMA | I3: SOLICITUD | J3: ASEGURADOR | K3: Buenas tardes Se está comunicando paciente en mención solicitando su programación de cita médica. Agradeceremos el contacto con la asegurada para su atención, al 943920495 | L3: SOLICITUD DE CITA | N3: MEDICA FAMILIAR - TELECONSULTA | O3: 45721 | P3: FUE ATENDIDA | Q3: 05/03/2025 6:40 PM VIVA 1A CENTRO MEDICO PERU Antonio David Moncada Catalan MEDICA FAMILIAR - TELECONSULTA PROCESADO 05/03/2025 | S3: ACTIVA
B4: 77742062 | C4: EDGAR IGNACIO DE LA TORRE RODRIGUEZ | E4: 994988665 | F4: jackelinrt2013@gmail.com | I4: QUEJAS Y RECLAMOS | J4: ASEGURADOR | K4: Madre del asegurado indica que hace un mes no se ponen en contacto para el seguimiento del programa CUIDATE por diagnóstico de asma y la gestión de envió de medicinas para su menor . Solicita que puedan llamarla en la brevedad posible | L4: NO ASIGNACIÓN DE CITA | M4: CUIDATE | N4: ASMA | O4: 45721 | S4: ACTIVA
B5: 7731756 | C5: LAURA LASERNA | I5: QUEJAS Y RECLAMOS | J5: ASEGURADOR | K5: Hola Ivon, he tenido 2 insidentes: 1 En el chequeo preventivo, no me tomaron la muestra de orina ni la densitometría ósea, cuando enviaste informacion este año, me di cuenta, llame a la clinica y me dieron cita para la densitometría ósea, pero el examen de orina no se podia porque ya habia pasado mas de 7 dias. 2 Estaba en el plan de otras enfermedades cronicas - hipotiroidismo, pero la reserva de cita y examenes, tenia que estar llamando al provedor, en diciembre se olvidaron y no llegaron a comunicarse conmigo. En febrero cambiaron de proveedor y tambien tuve que estar llamando por la cita medica porque se estaba terminando mi medicacion. Luego me llamaron y me indicaron que no podian darme la medicacion para el colesterol alto que mi plan no cubria, habiando estado llevando varios meses la misma medicacion, asi que me han cambiado de plan ahora estoy en deslipidemia. Este plan era muy bueno al principio, porque se tiene atencion medica, medicamentos y analisis de laboratorio, espero que el nuevo proveedor mejore No son consultas propiamente dicha pero me ha pasado. | L5: NO ASIGNACIÓN DE CITA | M5: PACIENTE CRONICO | N5: DISLIPIDEMIA | O5: 45726 | S5: ACTIVA
B6: 8185495 | C6: PATRICIA OCHOA LUBINOFF | E6: 969608702 | I6: QUEJAS Y RECLAMOS | J6: ASEGURADOR | K6: Vania buenas tardes. Hace dos meses me afilié al programa crónicos por hipotiroidismo. Me agendaron hace mes y medio la consulta médica y entregaron la medicina y nunca más se comunicaron conmigo hasta el sábado pasado que me llamaron del teléfono 6183000 (VIVA A1) indicándome que me estaban programando para esta semana y que me confirmarían, osea pasó un mes y medio. Supuestamente el compromiso era que las consultas son mensuales pues en mi caso, se olvidaron y como será con los afiliados que tenemos. Por lo expuesto y dado que me quieren programar sabe dios cuando, indicarme si puedo comprar la medicina (EUTIROX 74 MG) Y PASARLO POR REEMBOLSO bajo condiciones de este programa. Llamé a Rosa Baldeón de RIMAC que maneja este tema de crónicos pero no logré respuesta. Quedo atenta a sus noticias. | L6: NO ASIGNACIÓN DE CITA | M6: PACIENTE CRONICO | N6: HIPOTIROIDISMO | O6: 45727 | S6: ACTIVA
A7: DNI | B7: 46674191 | C7: VERONICA ANDREA TAMARIZ VALENTIN | E7: 959354515 | I7: QUEJAS Y RECLAMOS | J7: ASEGURADOR | K7: Hola Guissela por favor un apoyo con este caso con la cliente que es paciente crónico de hipotiroidismo, el cual comenta que el nuevo proveedor que viene trabajando con aviva 1 A no esta siendo eficiente ya que ella es la que tiene que llamar, preguntar, preocuparse por todo y si no llaman no agilizan nada según comenta. Indica que debe tienen que sacarle cita para atención de laboratorio y una cita pendiente de su ultima atención. NOMBRES: VERONICA ANDREA TAMARIZ VALENTIN DNI: 46674191 CELULAR: 959354515 POLIZA: E0002545 | L7: NO ASIGNACIÓN DE CITA | M7: PACIENTE CRONICO | N7: HIPOTIROIDISMO | O7: 45728 | P7: NO FUE ATENDIDA | Q7: 27/03/2025 2:10 PM VIVA 1A CENTRO MEDICO PERU Gerson Jacob Siura Trevejo Trevejo ENDOCRINOLOGÍA - TELECONSULTA FACTURADA 25/03/2025 | S7: ACTIVA
A8: DNI | B8: 6040784 | C8: JULIO RAFAEL MARTIN CAMPOS | E8: 997500213 | F8: rafomartincampos@gmail.com | I8: QUEJAS Y RECLAMOS | J8: ASEGURADOR | K8: Buenas tardes. Por favor su apoyo en coordinación de cita de clientes VIP que se encuentran en programa ESTAR VITAL. Favor de enviar mensaje por WhatsApp antes de llamar para que pueda contestar llamada, cliente tiene bloqueo SPAM y tiene que agregar a sus contactos para que le permita la recepción de llamadas. Cliente usualmente tiene las citas los primeros días, sin embargo, hasta el momento no lo contactan y se encuentra crítico, porque siempre tiene que reportar para que se pueda agendar su cita y entrega de medicamentos. Nombre: JULIO RAFAEL MARTIN CAMPOS DNI: 06040784 CEL CONTACTO:997500213 CORREO: rafomartincampos@gmail.com DIAGNOSTICO: DISLIPIDEMIA Nombre: MARIANA SOLE VARGAS DNI: 08275667 CEL CONTACTO:997500213 CORREO: rafomartincampos@gmail.com DIAGNOSTICO: HIPOTIROIDISMO, ARTROSIS, MIGRAÑA, OSTEOPOROSIS | L8: NO ASIGNACIÓN DE CITA | M8: PACIENTE CRONICO | N8: DISLIPIDEMIA | O8: 45728 | P8: NO FUE ATENDIDA | Q8: 13/03/2025 7:15 PM VIVA 1A CENTRO MEDICO PERU Antonio David Moncada Catalan MEDICA FAMILIAR - TELECONSULTA PROCESADO | S8: ACTIVA
A9: DNI | B9: 8275667 | C9: MARIANA SOLE VARGAS | E9: 997500213 | F9: rafomartincampos@gmail.com | I9: QUEJAS Y RECLAMOS | J9: ASEGURADOR | K9: Buenas tardes. Por favor su apoyo en coordinación de cita de clientes VIP que se encuentran en programa ESTAR VITAL. Favor de enviar mensaje por WhatsApp antes de llamar para que pueda contestar llamada, cliente tiene bloqueo SPAM y tiene que agregar a sus contactos para que le permita la recepción de llamadas. Cliente usualmente tiene las citas los primeros días, sin embargo, hasta el momento no lo contactan y se encuentra crítico, porque siempre tiene que reportar para que se pueda agendar su cita y entrega de medicamentos. Nombre: JULIO RAFAEL MARTIN CAMPOS DNI: 06040784 CEL CONTACTO:997500213 CORREO: rafomartincampos@gmail.com DIAGNOSTICO: DISLIPIDEMIA Nombre: MARIANA SOLE VARGAS DNI: 08275667 CEL CONTACTO:997500213 CORREO: rafomartincampos@gmail.com DIAGNOSTICO: HIPOTIROIDISMO, ARTROSIS, MIGRAÑA, OSTEOPOROSIS | L9: NO ASIGNACIÓN DE CITA | M9: PACIENTE CRONICO | N9: HIPOTIROIDISMO | O9: 45728 | P9: NO FUE ATENDIDA | Q9: FUE ATENDIDA 13/03/2025 7:00 PM VIVA 1A CENTRO MEDICO PERU Antonio David Moncada Catalan MEDICA FAMILIAR – TELECONSULTA | S9: ACTIVA
A10: DNI | B10: 44841514 | C10: CARINA MIRANDA LAZO | I10: QUEJAS Y RECLAMOS | J10: ASEGURADOR | K10: Buenas tardes Kenny / Kaila Solicito su gentil apoyo, cliente en mención cuenta con diabetes , se atiende en el programa CUIDATE, que era con STARVITAL, le informaron que lo contactarían para poder coordinar la cita médica programada, y la entrega de su medicina con el nuevo proveedor. Sin embargo, al momento no recibe comunicación, ni confirmación de la nueva cita. Indica necesitar sus medicinas de manera urgente por los diagnósticos que presenta .Adicional a ello indica que por favor se comuniquen vía WhatsApp ya que no responde teléfonos no registrados | L10: NO ASIGNACIÓN DE CITA | M10: CUIDATE | N10: NO ESPECIFICA | O10: 45735 | P10: NO FUE ATENDIDA | Q10: FUE ATENDIDA 20/03/2025 7:45 PM VIVA 1A CENTRO MEDICO PERU Gerson Jacob Siura Trevejo Trevejo ENDOCRINOLOGÍA - TELECONSULTA PROCESADO 17/03/2025 GADIAZHUAJAN CONFIRMACION DE CITA | S10: ACTIVA
B11: 7806297 | C11: VICTOR BARUA ALZAMORA | I11: QUEJAS Y RECLAMOS | J11: ASEGURADOR | K11: Estimada Guissela El 14 Feb 25 los señores de Viva A1 le brindaron la atencion medica al Sr. Fernando Barua Alzamora otorgando la medicación prescrita por el medico tratante por 30 dias. Es el caso que el control del mes Marzo debió ser el 15/03 hasta el día de hoy no se le ha brindado la atencion medica correspondiente por consiguiente no cuenta con medicación. El día de hoy he conversado con la Lic. Gianina Cigueñas quien me manifestó que la Dra. Anahis Seigas no le confirmaba la consulta, ya que ella estaba laborando en otro lugar. Que hacemos, por el estado de salud del Sr. Barua el no puede dejas de tomar su medicación, por eso requiero su apoyo a fin de que el día de hoy se le haga entrega de sus medicamentos. Esta situación no puede volver a repetirse, no pueden perjudicar de esta manera al asegurado, por lo que le solicito conversar con los señores de Viva A1 para que lleven un mejor control de las atenciones de los asegurados Quedo a la espera de su respuesta a lo solicitado. Saludos cordiales | L11: NO ASIGNACIÓN DE CITA | N11: NO ESPECIFICA | O11: 45736 | S11: ACTIVA
A12: DNI | B12: 42764761 | C12: HENRY WILLIAM CASTILLO JARA | G12: 25-EPS002420 | I12: QUEJAS Y RECLAMOS | J12: ASEGURADOR | K12: Buenas tardes estimados, Paciente de nuestro programa de enfermedades crónicas refiere que médico envió orden de lab. Anti TPO hace 2 meses, pero hasta el momento no le han realizado el examen, su gentil apoyo en cobertura de ese examen solicitado por el Dr. Gerson Siura, y así pueda ser evaluado con los resultados en su próxima consulta médica, su gentil apoyo en revisión del caso, por favor. PX: HENRY WILLIAM CASTILLO JARA DNI: 42764761 DX: Hipotiroidismo Quedamos pendientes | L12: NO ASIGNACIÓN DE CITA | M12: PRESTADOR EXTERNO | N12: LABORATORIO | O12: 45740 | Q12: NO SE CUENTA CON INFORMACIÓN | S12: ACTIVA
A13: DNI | B13: 7823787 | C13: DINA RAQUEL QUIROZ VELASQUEZ | I13: QUEJAS Y RECLAMOS | J13: ASEGURADOR | K13: Katherine buenas tardes, Cliente se comunica porque quedaron en llamarle entre ayer y hoy para coordinar su cita (porque se inscribió el jueves de la semana pasada) y le indicaron que en 72 horas le llamarían, pero no se comunican con ella aún. Solicita apoyo para que le llamen y separar su cita. DINA RAQUEL QUIROZ VELASQUEZ DNI 07823787 DIAGNOSITO Dislipidemia - Hipertensión PÓLIZA E0002545 TELEFONO 988243995 Sls, | L13: NO ASIGNACIÓN DE CITA | N13: NO ESPECIFICA | O13: 45741 | P13: NO FUE ATENDIDA | Q13: 02/04/2025 9:30 AM VIVA 1A CENTRO MEDICO PERU Virginia Cuevas Rivero MEDICA FAMILIAR - TELECONSULTA PROCESADO 01/04/2025 | S13: ACTIVA
A14: DNI | B14: 25677282 | C14: ROXANA ESPERANZA TAVERA D ANGELO | E14: 991888565 | I14: QUEJAS Y RECLAMOS | J14: ASEGURADOR | K14: Hola Andrés, gracias por tu llamada. Paso a comentarte lo sucedido con mi atención como Paciente del Programa Cuídate de Rimac. Me llamó la atención que no me llamaran para darme cita con el doctor, como todos los meses, y dijeron que ya no trabajaban con Rimac. Me contacté con ustedes y me asignaron a “Viva 1A”. Me dieron cita para el viernes 7 de marzo pasado. Me mandaron por mail mi receta de medicamentos y me mandaron hacer unos análisis. Hasta el lunes 10 nadie se había comunicado conmigo para coordinar entrega de mis medicinas ni toma de análisis. Los teléfonos que tenía de “Viva 1A”, me contesta un Robot, tanto por teléfono como por WhatsApp, y como mi pregunta no estaba dentro de sus alternativas, colgaban. Luego que los molesté a ustedes, me llamaron y recién ayer miércoles, me entregaron mis medicamentos. Pero para los análisis aún no se contactan conmigo. Pongo estos comentarios para tomen la mejor decisión, en vista que no puedo estar sin tomar esas medicinas. Saludos, | L14: NO ASIGNACIÓN DE CITA | M14: PRESTADOR EXTERNO | N14: LABORATORIO | O14: 45741 | P14: CITA PENDIENTE | Q14: 04/04/2025 8:00 AM VIVA 1A CENTRO MEDICO PERU Virginia Cuevas Rivero MEDICA FAMILIAR - TELECONSULTA ACTIVO 01/04/2025- PTE SOLICITA LABORATORIOS PENDIENTES | S14: ACTIVA
C15: BASILIO ALFONSO CESARO STROBBE | I15: QUEJAS Y RECLAMOS | J15: ASEGURADOR | K15: Buenas tardes: Por favor, para su atención. 1. Contacto (Apellidos y Nombres) : CONSUELO ROCIO LORA DESCALZO DE CESARO 2. Número de Póliza y Certificado: E0028656 3. Mail : rocio.lora@gmail.com telefono: 990265336 4. Observación: paciente BASILIO ALFONSO CESARO STROBBE se atendio por ultima vez hace mas de un mes y quedo pendiente su evaluacion cardiologica | L15: NO ASIGNACIÓN DE CITA | N15: RIESGO CARDIOVASCULAR | O15: 45741 | S15: ACTIVA
A16: DNI | B16: 72844745 | C16: DIEGO VASQUEZ IGLESIAS | I16: SOLICITUD | J16: ASEGURADOR | K16: Estimados @quejasyreclamos@viva1a.com.pe@admisionrimac@viva1a.com.pe Por favor se requiere el descargo y la pronta atención del usuario referido. Buenos días: Por favor paciente pertenece al programa CUIDATE diagnóstico HIPERTENSION ARTERIAL y nos informa que no le envían sus medicinas desde hace dos meses. DNI:72844745 DIEGO ALEJANDRO VASQUEZ IGLESIAS TELEFONO: 954775445 CORREO: diegoiglesiasvasquez@gmail.com Póliza : EPS Atte. 31/03/2025 Lo que se encuentra pendiente de atención es: La programación de la cita de control médico presencial. La coordinación para la toma de exámenes de laboratorio de seguimiento. | L16: SOLICITUD DE CITA | M16: CUIDATE | N16: HIPERTENSION | O16: 45742 | P16: FUE ATENDIDA | Q16: 26/03/2025 6:00 PM VIVA 1A CENTRO MEDICO PERU Hilton D Jango Cruz CARDIOLOGIA - ATENCIÓN DOMICILIARIA PROCESADO 26/03/2025 GSIGUENAS INGRESO HTA MANTENER BETALOC | ILTUX | S16: ACTIVA
C17: LUZ VELASQUEZ MUÑOZ | E17: 982491420 | I17: SOLICITUD | J17: ASEGURADOR | K17: Hola Gissela, Agradeceré tu apoyo con el presente reclamo, paciente Luz Velasquez Muñoz indica que hasta el momento no puede atenderse a través del programa Cuidate. Por favor tu apoyo a fin de contactarse con la asegurada y puedan brindarle la información del programa. DATOS: Luz Angelica Velasquez Muñoz Celular: 982491420 Quedo atenta a tu pronta respuesta. Saludos, | L17: SOLICITUD DE CITA | M17: CUIDATE | N17: NO ESPECIFICA | O17: 45742 | S17: ACTIVA
B18: 71528818 | C18: VALERIA XIMENA AGUIRRE VALER | G18: 25-SBS013956 | I18: QUEJAS Y RECLAMOS | J18: LIBRO DE RECLAMOS ASEGURADOR | K18: "Asegura manifiesta su incomodidad debido a que lleva ya 7 llamadas en las cuales solicita un médico virtual y hasta el momento no tiene respuesta alguna. Recipen el proveedor menciona que a partir de las 2 pm van a poder atenderla. Adicional a ello, no esta conforme con el proveedor aviva para proximas atenciones requiere a la clínica internacional." | L18: NO ASIGNACIÓN DE CITA | N18: NO ESPECIFICA | O18: 45737 | S18: ACTIVA
A19: DNI | B19: 41411250 | C19: VICTOR ARCADIO BERNAL FUENTES | E19: 951303432 | H19: 24819056 | I19: SOLICITUD | J19: WHASTAPP | K19: FUE ATENDIDO EL 24/03 Y SOLICTA SEGUIMIENTO | L19: SOLICITUD DE CITA | M19: MEDICINA GENERAL | N19: MEDICINA GENERAL | O19: 45742 | P19: FUE ATENDIDA | Q19: 26/03/2025 9:30 AM VIVA 1A CENTRO MEDICO PERU Greduin Alexander Romero Bompart MEDICINA GENERAL – TELECONSULTA- PTE SOLICITA SEGUIMIENTO | S19: ACTIVA
A20: DNI | C20: KAORI DANIELA INGA BALDEON | E20: 992770160 | H20: 24838224 | I20: SOLICITUD | J20: WHASTAPP | K20: SOLICTA PROGRAMACION 3:30PM | L20: SOLICITUD DE CITA | M20: MEDICINA GENERAL | N20: MEDICINA GENERAL | O20: 45742 | S20: ACTIVA
A21: DNI | B21: 41247452 | C21: JOSE CARLOS FARFAN HUAMAN | E21: 915375368 | H21: 24838255 | I21: SOLICITUD | J21: WHASTAPP | K21: MEDICO NO INGRESO AL LINK | L21: NO ATENCION DE CITA PROGRAMADA | M21: MEDICINA GENERAL | N21: MEDICINA GENERAL | O21: 45742 | P21: FUE ATENDIDA | Q21: 26/03/2025 9:40 AM VIVA 1A CENTRO MEDICO PERU Lourdes Vanesa Molina Acurio MEDICINA GENERAL - TELECONSULTA CENTRO MÉDICO VIRTUAL PROCESADO 26/03/2025 DDELEON Cita oficina virtual RIMAC S.A EPS | S21: ACTIVA
A22: DNI | B22: 43454029 | C22: DANIEL CLAUDIO ORBEGOSO CANCHIS | E22: 997610020 | H22: 24837859 | I22: SOLICITUD | J22: WHASTAPP | K22: MEDICO NO INGRESO AL LINK | L22: NO ATENCION DE CITA PROGRAMADA | M22: MEDICINA GENERAL | N22: MEDICINA GENERAL | O22: 45742 | P22: FUE ATENDIDA | Q22: 26/03/2025 10:00 AM VIVA 1A CENTRO MEDICO PERU Lourdes Vanesa Molina Acurio MEDICINA GENERAL - TELECONSULTA CENTRO MÉDICO VIRTUAL FACTURADA 26/03/2025 GADIAZHUAJAN | S22: ACTIVA
A23: DNI | B23: 47623959 | C23: KATHERINE KELLY BALLENA LARA | E23: 997895326 | H23: 24838471 | I23: QUEJAS Y RECLAMOS | J23: WHASTAPP | K23: MEDICO NO INGRESO AL LINK | L23: NO ATENCION DE CITA PROGRAMADA | M23: MEDICINA GENERAL | N23: MEDICINA GENERAL | O23: 45742 | P23: FUE ATENDIDA | Q23: 26/03/2025 10:20 AM VIVA 1A CENTRO MEDICO PERU Lourdes Vanesa Molina Acurio MEDICINA GENERAL - TELECONSULTA CENTRO MÉDICO VIRTUAL PROCESADO 26/03/2025 | S23: ACTIVA
A24: DNI | B24: 41380020 | C24: JESSICA CAROLINA RAMOS LINARES | E24: 906868565 | H24: 24822103 | I24: SOLICITUD | J24: WHASTAPP | K24: ECIBIO ATENCION VIRTUAL HACE 48 HORAS PROVEEDOR VIVA, DESEA QUE LA LLAMEN PARA REALIZAR SEGUIMIENTO YA QUE PACIENTE AUN NO SE ENCUENTRA BIEN | L24: SOLICITUD DE CITA | M24: MEDICINA GENERAL | N24: MEDICINA GENERAL | O24: 45742 | P24: FUE ATENDIDA | Q24: FUE ATENDIDA EL 26/03/2025 HISTORIA CLINICA NO REGISTRA EN EVEREST | S24: ACTIVA
A25: DNI | B25: 47622115 | C25: DAVID EDUARDO GOMEZ BOLUARTE | E25: 949574468 | H25: 24838076 | I25: SOLICITUD | J25: WHASTAPP | K25: FUE ATENDIDO EL 26/03 REFIERE QUE AUN PERSITE DOLOR , SEGUIMIENTO CMV | L25: SOLICITUD DE CITA | M25: MEDICINA GENERAL | N25: MEDICINA GENERAL | O25: 45743 | P25: FUE ATENDIDA-SEGUIMIENTO | Q25: 26/03/2025 8:00 AM VIVA 1A CENTRO MEDICO PERU Lourdes Vanesa Molina Acurio MEDICINA GENERAL - TELECONSULTA CENTRO MÉDICO VIRTUAL PROCESADO PTE SOLICTA SEGUIMIENTO | S25: ACTIVA
A26: DNI | B26: 91040753 | C26: FRANCO GABRIEL RODRIGUEZ ALPACA | E26: 996714343 | H26: 24836654 | I26: SOLICITUD | J26: WHASTAPP | K26: FUE ATENDIDA 25/03 , PRESENTA REACCION ALERGICA | L26: SOLICITUD DE CITA | M26: MEDICINA ESPECIALIZADA | N26: PEDIATRIA | O26: 45743 | P26: FUE ATENDIDA-SEGUIMIENTO | Q26: 28/03/2025 8:55 PM VIVA 1A CENTRO MEDICO PERU Eliana Jose Jaramillo Del Valle PEDIATRÍA - TELECONSULTA CENTRO MÉDICO VIRTUAL PROCESADO 28/03/2025 PTE SOLICITA SEGUIMIENTO | S26: ACTIVA
A27: DNI | B27: 5887878 | C27: JOAQUIN TALLEDO CASTRE | E27: 998111946 | H27: 24847536 | I27: SOLICITUD | J27: WHASTAPP | K27: REPROGRAMACION | L27: SOLICITUD DE CITA | M27: MEDICINA ESPECIALIZADA | N27: PEDIATRIA | O27: 45743 | P27: FUE ATENDIDA | Q27: 27/03/2025 12:25 732148 0024850342 - JOAQUIN TALLEDO CASTRE SANTIAGO DE SURCO Médico Virtual Pediatría 27/03/2025 13:00 | S27: ACTIVA
A28: DNI | B28: 44632024 | C28: KRISTY JOYCE NEVELYN ARTEAGA MOYA | E28: 936628006 | H28: 24838101 | I28: SOLICITUD | J28: WHASTAPP | K28: AUN PERSITE LOS SINTOMAS | L28: SOLICITUD DE CITA | M28: MEDICINA ESPECIALIZADA | N28: MEDICINA GENERAL | O28: 45744 | P28: FUE ATENDIDA | Q28: 31/03/2025 4:40 PM VIVA 1A CENTRO MEDICO PERU Adriana Espinoza Hoempler MEDICINA GENERAL - TELECONSULTA CENTRO MÉDICO VIRTUAL ACTIVO 31/03/2025 | S28: ACTIVA
A29: DNI | B29: 79775077 | C29: KLAUS MITTERHOFER HARMSEN | E29: 945669028 | H29: 24855022 | I29: SOLICITUD | J29: WHASTAPP | K29: Madre de menor informa que su hijo persiste con tos y no le han dejado medicación para la toS.seguimiento | L29: SOLICITUD DE CITA | M29: MEDICINA ESPECIALIZADA | N29: MEDICINA GENERAL | O29: 45744 | P29: FUE ATENDIDA-SEGUIMIENTO | Q29: 31/03/2025 4:40 PM VIVA 1A CENTRO MEDICO PERU Adriana Espinoza Hoempler MEDICINA GENERAL - TELECONSULTA CENTRO MÉDICO VIRTUAL - | S29: ACTIVA
A30: DNI | B30: 76239331 | C30: ALYSON NICOL TOVAR ALCALA | E30: 940923302 | H30: 24857484 | I30: QUEJAS Y RECLAMOS | J30: WHASTAPP | K30: paciente con MV programado a las 10:20am refiere que medico no ingresa a link. | L30: NO ATENCION DE CITA PROGRAMADA | N30: NO ESPECIFICA | O30: 45744 | P30: FUE ATENDIDA | Q30: 28/03/2025 11:10 AM VIVA 1A CENTRO MEDICO PERU Marciel Espinoza Noguera MEDICINA GENERAL - TELECONSULTA CENTRO MÉDICO VIRTUAL FACTURADA 28/03/2025 | S30: ACTIVA
A31: DNI | B31: 46603235 | C31: JOANA CRISTINA RAYGADA RISCO | I31: SOLICITUD | J31: ASEGURADOR | K31: Su urgente apoyo con atender el requerimiento de la usuaria. Buenas tardes estimados, Se verifica que la paciente tuvo consulta el 10/03 con el Dr. Moncada. No obstante, recientemente ha sido informada de su embarazo. Siguiendo la recomendación de su ginecóloga, se ha indicado que consulte con su médico tratante del programa Cuídate, debido a su diagnóstico de hipertensión arterial (HTA), con el fin de evaluar la continuidad de su tratamiento farmacológico. Por lo que se brinda el visto bueno para proceder con la reevaluación del médico tratante del programa a la brevedad posible de manera excepcional, de antemano gracias por el apoyo. | L31: SOLICITUD DE CITA | M31: CRONICOS | N31: HIPERTENSION | O31: 45744 | P31: NO FUE ATENDIDA | Q31: NO FUE ATENDIDA | S31: ACTIVA
A32: DNI | B32: 9994334 | C32: ANA GABRIELA CHAVEZ VARGAS | E32: 989640563 | I32: QUEJAS Y RECLAMOS | J32: ASEGURADOR | K32: Estimados buenos días, se acaba de comunicar conmigo la señora ANA CHAVEZ, quien indica que hasta ahorita no la llaman para poder generar sus exámenes de laboratorio y que cuando escribe al número de whatssap solo le responde una bot. Por favor su apoyo para poder llamara lo antes posible. TLF: 989 640 563 | L32: NO ASIGNACIÓN DE CITA | M32: PRESTADOR EXTERNNO | N32: LABORATORIO | O32: 45747 | S32: ACTIVA
A33: DNI | B33: 7218366 | C33: GLADYS PATRICIA GUTIERREZ VELEZMORO | I33: QUEJAS Y RECLAMOS | J33: ASEGURADOR | K33: RIMAC VIP//PROGRAMA CRONICOS REUMATOLOGIA//GLADYS PATRICIA GUTIERREZ VELEZMORO | L33: NO ASIGNACIÓN DE CITA | M33: CRONICOS | N33: REUMATOLOGIA | O33: 45716 | P33: PROGRAMA CRONICOS | S33: ACTIVA
A34: DNI | B34: 8287353 | C34: LEON MAGNO SANCHEZ QUINTANILLA | I34: QUEJAS Y RECLAMOS | J34: ASEGURADOR | K34: programa cuídate / LEON MAGNO SANCHEZ QUINTANILLA | L34: NO ASIGNACIÓN DE CITA | M34: CUIDATE | N34: NO ESPECIFICA | O34: 45716 | P34: PROGRAMA CRONICOS | S34: ACTIVA
A35: DNI | B35: 44000062 | C35: LLAMOJA VICENTE DENNISE | I35: QUEJAS Y RECLAMOS | J35: ASEGURADOR | K35: CUIDATE- PROGRAMA CRONICO | L35: NO ASIGNACIÓN DE CITA | M35: CUIDATE | N35: NO ESPECIFICA | O35: 45716 | P35: PROGRAMA CRONICOS | S35: ACTIVA
C36: POTENCIALES AL PROGRAMA CUIDATE Y OTROS CRONICOS-SURA /RIESGO | I36: SOLICITUD | J36: ASEGURADOR | K36: POTENCIALES AL PROGRAMA CUIDATE Y OTROS CRONICOS-SURA /RIESGO | L36: SOLICITUD DE CITA | M36: CUIDATE | N36: NO ESPECIFICA | O36: 45712 | S36: ACTIVA
A37: DNI | B37: 9876517 | C37: Victor Edgar Solis Plaza | I37: QUEJAS Y RECLAMOS | J37: ASEGURADOR | K37: REFINERIA LA PAMPILLA / EPS N° E0001009 / ASEGURADO: Victor Edgar Solis Plaza / RECLAMO URGENTE | L37: NO ASIGNACIÓN DE CITA | N37: NO ESPECIFICA | O37: - | P37: PROGRAMA CRONICOS | S37: ACTIVA
A38: DNI | B38: 8170776 | C38: NILTON HERMAN JIMENEZ ROSALES | I38: SOLICITUDES | J38: ASEGURADOR | K38: CONTINUDAD DE TERAPIAS FISICAS USUARIO NILTON HERMAN JIMENEZ ROSALES DNI:08170776 -DIAMANTE | L38: SOLICITUD DE CITA | M38: TERAPIAS | N38: TERAPÍA FISICA | O38: 45734 | P38: PROGRAMA CRONICOS | S38: ACTIVA
A39: DNI | B39: 72154157 | C39: FIORELLA CRISEL VERGARA OLIVO | I39: QUEJAS Y RECLAMOS | J39: ASEGURADOR | K39: CONDICIONES DE CONTRATO CON EL PRESTADOR PARA ATENCION A PACIENTE EN MENCION | L39: NO ASIGNACIÓN DE CITA | N39: NO ESPECIFICA | O39: 45733 | P39: PROGRAMA CRONICOS | S39: ACTIVA
